Workbook

Sheet Product Backlog
A1: Product Name: | B1: Exceptional Laptops and Supercomputers Always (ELSA) | I1: Complete Fields in Green!!!
A2: Team ID:
B4: Team Member Name | H4: Initials | I4: Student ID
A5: Required
A11: Sprint # | B11: Remaining | C11: Completed This Sprint | G11: Comment
A12: 0 | B12: =COUNT(B24:B127) -> 22 | F12: Total | G12: Total number of features (in column H)
A13: 1 | B13: =B12-C13 -> 22 | C13: =COUNTIF(G$24:G$101,"Finished in Sprint 1") -> 0 | F13: 1 | G13: Total features left at the end of Sprint #1
A14: 2 | B14: =B13-C14 -> 22 | C14: =COUNTIF(G$24:G$101,"Finished in Sprint 2") -> 0 | F14: 2 | G14: Total features left at the end of Sprint #2
A15: 3 | B15: =B14-C15 -> 22 | C15: =COUNTIF(G$24:G$101,"Finished in Sprint 3") -> 0 | F15: 3 | G15: ...and so on
A16: 4 | B16: =B15-C16 -> 22 | C16: =COUNTIF(G$24:G$101,"Finished in Sprint 4") -> 0
A17: 5 | B17: =B16-C17 -> 22 | C17: =COUNTIF(G$24:G$101,"Finished in Sprint 4") -> 0
H20: Note: Priority and specs for unfinished Features is subject to change at the end of each sprint at the whim of the Product Owner
H21: Additional features may be proposed by the student but must be approved by the Product Owner in writing
F22: Sprints
A23: Feature ID | B23: Priority | C23: Required | D23: Bonus | E23: Est | F23: Planned | G23: Status | H23: As a... | I23: I want to... | J23: So that I can… | K23: Notes
A24: CUST | B24: 1 | C24: 1 | E24: 3 | H24: Sales Staff | I24: Remember each customer’s name and contact info | J24: Ship them products repeatedly
A25: OPT | B25: 2 | C25: 1 | E25: 8 | H25: Inventory | I25: Maintain a list of options for a desktop (e.g., disk, RAM, CPU) | J25: Select them when designing a new desktop product
A26: DESKT | B26: 3 | C26: 1 | E26: 8 | H26: Sales Staff | I26: Define a new desktop configuration from options | J26: Can quickly customize products for my customers
A27: ORDER | B27: 4 | C27: 1 | E27: 13 | H27: Sales Staff | I27: Associate a customer with one or more desktops into an order | J27: Keep track of who has bought what
A28: WIN | B28: 5 | C28: 2 | E28: 21 | H28: Sales Staff | I28: Replace text interface with GUI main window | J28: Use it more easily | K28: Recommend baselining Nim from Lecture 13
A29: OUTM | B29: 6 | C29: 2 | E29: 5 | H29: Sales Staff | I29: Replace list of data records with main window list | J29: Access the data directly in the window | K29: Try using std::ostringstream to capture operator<< formatting
A30: INDIA | B30: 7 | C30: 2 | E30: 8 | H30: Sales Staff | I30: Replace data queries with series of dialogs | J30: Do everything within the GUI | K30: Recommend baselining EntryDialog from Lecture 14
A31: ABOUT | B31: 8 | C31: 2 | E31: 1 | H31: Director | I31: Provide About dialog for documenting licenses | J31: Avoid a lawsuit
A32: SAVE | B32: 9 | C32: 3 | E32: 13 | H32: Manager | I32: Save the data to a default file (File > Save) | J32: Persist our data through the years | K32: This requires modifying the “model” to save and reload each object from a provided stream
A33: SAVAS | B33: 10 | C33: 3 | E33: 5 | H33: Manager | I33: Save the data to a specified file (File > Save As) | J33: Persist our data through the years | K33: Use Gtk::FileChooser
A34: LOAD | B34: 11 | C34: 3 | E34: 8 | H34: Manager | I34: Load the data from a specified file (File > Open) | J34: Persist our data through the years | K34: Use Gtk::FileChooser
A35: QRAM | B35: 12 | C35: 4 | E35: 21 | H35: Customer | I35: Store and display additional RAM data | J35: Ensure I purchase the correct product
A36: DCUST | B36: 13 | C36: 4 | E36: 8 | H36: Sales Staff | I36: Replace Insert Customer dialogs with single dialog | J36: Enter data more quickly
I38: BONUS WORK – COMPLETE ABOVE FEATURES FIRST!!!
A40: QCPU | B40: 14 | D40: 25 | E40: 13 | H40: Customer | I40: Store and display additional CPU data | J40: Ensure I purchase the correct product | K40: Derive classes from Options and call operator<< polymorphically
A41: QDISK | B41: 15 | D41: 10 | E41: 5 | H41: Customer | I41: Store and display additional Disk data | J41: Ensure I purchase the correct product
A42: DORD | B42: 16 | D42: 15 | E42: 8 | H42: Sales Staff | I42: Replace Insert Order dialogs with single dialog | J42: Enter data more quickly
A43: DOPT | B43: 17 | D43: 40 | E43: 21 | H43: Sales Staff | I43: Replace Insert Option dialogs with single dialog | J43: Enter data more quickly
A44: DDESK | B44: 18 | D44: 25 | E44: 13 | H44: Sales Staff | I44: Replace Insert Desktop dialogs with single dialog | J44: Enter data more quickly
A45: TBAR | B45: 19 | D45: 10 | E45: 5 | H45: Customer | I45: Access key functionality with a toolbar AND menu | J45: More quickly access the behaviors I need | K45: You can baseline this code from Nim’s Mainwin::Mainwin as well
A46: SCROL | B46: 20 | D46: 10 | E46: 5 | H46: Customer | I46: Make the main window’s data area scrollable | J46: See large volumes of data | K46: The exact settings (e.g., are the scrollbars always visible or only when scrolling is available?) are up to you
A47: DEPR | B47: 21 | D47: 25 | E47: 13 | H47: Inventory | I47: Deprecate a product | J47: Avoid selling products that are out of production | K47: This requires a Boolean with getter and setter in the Options and Desktop classes to indicate which are deprecated. The index number may pose interesting challenges, since deprecation will create gaps.
A48: SBAR | B48: 22 | D48: 15 | E48: 8 | H48: Manager | I48: Replace the Gtk::Label for the status bar with Gtk::Statusbar, and maintain a message stack | J48: Better track status of messages | K48: Just swapping Gtk::Statusbar for Gtk::Label is trivial. Think through how to manage a first-in last-out stack of messages

Sheet Sprint 01 Backlog
A1: Sprint # | B1: 1 | D1: Complete Fields in Green!!!
A2: Start on | B2: 43893 | D2: *** Create a new Sprint Backlog for EVERY SPRINT ***
A3: End on | B3: =B2+21 -> 43914
A4: Demo on | B4: TBD
B6: Remaining | C6: Completed (this day)
A7: Total Tasks | B7: =COUNTA(D17:D995) -> 16
A8: Day 1 Left | B8: =B7-C8 -> 16 | C8: =COUNTIF(E$17:E$995, "Completed Day 1") -> 0
A9: Day 2 Left | B9: =B8-C9 -> 16 | C9: =COUNTIF(E$17:E$995, "Completed Day 2") -> 0
A10: Day 3 Left | B10: =B9-C10 -> 16 | C10: =COUNTIF(E$17:E$995, "Completed Day 3") -> 0
A11: Day 4 Left | B11: =B10-C11 -> 16 | C11: =COUNTIF(E$17:E$995, "Completed Day 4") -> 0
A12: Day 5 Left | B12: =B11-C12 -> 16 | C12: =COUNTIF(E$17:E$995, "Completed Day 5") -> 0
A13: Day 6 Left | B13: =B12-C13 -> 16 | C13: =COUNTIF(E$17:E$995, "Completed Day 6") -> 0
A14: Day 7 Left | B14: =B13-C14 -> 16 | C14: =COUNTIF(E$17:E$995, "Completed Day 7") -> 0
A16: Task ID | B16: Feature ID | C16: Assigned To | D16: Description | E16: Status | F16: Notes
A17: 1 | B17: CUST | D17: Write the Customer class | F17: Test each class and method as it is written
A18: 2 | B18: CUST | D18: Write operator<< for Customer | F18: Commit and push AT LEAST once every class or update
A19: 3 | B19: CUST | D19: Write Store::add_customer, num_customers, and customer | F19: You are free to determine your own algorithm for mapping the (now) 21 days of this sprint to the 7 reporting days – e.g., 1/3 days, the first 7 days you actually do work, etc.
A20: 4 | B20: OPT | D20: Write the Options class sans to_string
A21: 5 | B21: OPT | D21: Write Options::to_string and its operator<<
A22: 6 | B22: OPT | D22: Write Store::add_option (to Store), num_options, and option
A23: 7 | B23: DESKT | D23: Write the Desktop class with add_option method
A24: 8 | B24: DESKT | D24: Write the Desktop::price method
A25: 9 | B25: DESKT | D25: Write operator<< for Desktop
A26: 10 | B26: DESKT | D26: Write Store::new_desktop, add_option (to desktop), num_desktops, and desktop
A27: 11 | B27: ORDER | D27: Write the Order associative class and constructor
A28: 12 | B28: ORDER | D28: Write Order::add_product
A29: 13 | B29: ORDER | D29: Write Order::price
A30: 14 | B30: ORDER | D30: Write Store::new_order, add_desktop, num_orders, and order
A31: 15 | B31: ORDER | D31: Integrate and test with cse1325_prof/elsa/sprint_1/main.cpp
A32: 16 | B32: ORDER | D32: Ensure ALL CODE is on GitHub by deadline!
A33: 17
A34: 18
A35: 19
A36: 20
A37: 21
A38: 22
A39: 23
A40: 24
A41: 25
A42: 26
...

Sheet Sprint 02 Backlog
A1: Sprint # | B1: ='Sprint 01 Backlog'!B1+1 -> 2 | D1: Complete Fields in Green!!!
A2: Start on | B2: ='Sprint 01 Backlog'!B3 -> 43914 | D2: *** Create a new Sprint Backlog for EVERY SPRINT ***
A3: End on | B3: =B2+7 -> 43921
A4: Demo on | B4: TBD
B6: Remaining | C6: Completed (this day)
A7: Total Tasks | B7: =COUNTA(D17:D995) -> 6
A8: Day 1 Left | B8: =B7-C8 -> 6 | C8: =COUNTIF(E$17:E$995, "Completed Day 1") -> 0
A9: Day 2 Left | B9: =B8-C9 -> 6 | C9: =COUNTIF(E$17:E$995, "Completed Day 2") -> 0
A10: Day 3 Left | B10: =B9-C10 -> 6 | C10: =COUNTIF(E$17:E$995, "Completed Day 3") -> 0
A11: Day 4 Left | B11: =B10-C11 -> 4 | C11: 2
A12: Day 5 Left | B12: =B11-C12 -> 3 | C12: 1
A13: Day 6 Left | B13: =B12-C13 -> 3 | C13: =COUNTIF(E$17:E$995, "Completed Day 6") -> 0
A14: Day 7 Left | B14: =B13-C14 -> 2 | C14: 1
A16: Task ID | B16: Feature ID | C16: Assigned To | D16: Description | E16: Status | F16: Notes
A17: 1 | B17: WIN | D17: make mainwin class | F17: completed in day 4
A18: 2 | B18: WIN | D18: Write header file | F18: Complete in day 4
A19: 3 | B19: WIN | D19: Write::MenuItems | F19: Completed in day 5
A20: 4 | B20: WIN | D20: Wrire::On_view and on_insert methods | F20: Completed in day 7
A21: 5 | B21: OUTM | D21: Replace list od datat records with main window list
A22: 6 | B22: ABOUT | D22: Provide about dialog for documentation
A23: 7
A24: 8
A25: 9
A26: 10
A27: 11
A28: 12
A29: 13
A30: 14
A31: 15
A32: 16
A33: 17
A34: 18
... A100: 84

Sheet Sprint 03 Backlog
A1: Sprint # | B1: ='Sprint 02 Backlog'!B1+1 -> 3 | D1: Complete Fields in Green!!!
A2: Start on | B2: ='Sprint 02 Backlog'!B2+7 -> 43921 | D2: *** Create a new Sprint Backlog for EVERY SPRINT ***
A3: End on | B3: =B2+7 -> 43928
A4: Demo on | B4: TBD
B6: Remaining | C6: Completed (this day)
A7: Total Tasks | B7: =COUNTA(D17:D995) -> 1
A8: Day 1 Left | B8: =B7-C8 -> 1 | C8: =COUNTIF(E$17:E$995, "Completed Day 1") -> 0
A9: Day 2 Left | B9: =B8-C9 -> 1 | C9: =COUNTIF(E$17:E$995, "Completed Day 2") -> 0
A10: Day 3 Left | B10: =B9-C10 -> 1 | C10: =COUNTIF(E$17:E$995, "Completed Day 3") -> 0
A11: Day 4 Left | B11: =B10-C11 -> 1 | C11: =COUNTIF(E$17:E$995, "Completed Day 4") -> 0
A12: Day 5 Left | B12: =B11-C12 -> 1 | C12: =COUNTIF(E$17:E$995, "Completed Day 5") -> 0
A13: Day 6 Left | B13: =B12-C13 -> 1 | C13: =COUNTIF(E$17:E$995, "Completed Day 6") -> 0
A14: Day 7 Left | B14: =B13-C14 -> 1 | C14: =COUNTIF(E$17:E$995, "Completed Day 7") -> 0
A16: Task ID | B16: Feature ID | C16: Assigned To | D16: Description | E16: Status | F16: Notes
A17: 1 | D17: --> Add tasks to complete each feature for this sprint
A18: 2
A19: 3
A20: 4
A21: 5
A22: 6
A23: 7
A24: 8
A25: 9
A26: 10
A27: 11
A28: 12
A29: 13
... A100: 84

Sheet Sprint 04 Backlog
A1: Sprint # | B1: ='Sprint 03 Backlog'!B1+1 -> 4 | D1: Complete Fields in Green!!!
A2: Start on | B2: ='Sprint 03 Backlog'!B2+14 -> 43935 | D2: *** Create a new Sprint Backlog for EVERY SPRINT ***
A3: End on | B3: =B2+14 -> 43949
A4: Demo on | B4: TBD
B6: Remaining | C6: Completed (this day)
A7: Total Tasks | B7: =COUNTA(D17:D995) -> 1
A8: Day 1 Left | B8: =B7-C8 -> 1 | C8: =COUNTIF(E$17:E$995, "Completed Day 1") -> 0
A9: Day 2 Left | B9: =B8-C9 -> 1 | C9: =COUNTIF(E$17:E$995, "Completed Day 2") -> 0
A10: Day 3 Left | B10: =B9-C10 -> 1 | C10: =COUNTIF(E$17:E$995, "Completed Day 3") -> 0
A11: Day 4 Left | B11: =B10-C11 -> 1 | C11: =COUNTIF(E$17:E$995, "Completed Day 4") -> 0
A12: Day 5 Left | B12: =B11-C12 -> 1 | C12: =COUNTIF(E$17:E$995, "Completed Day 5") -> 0
A13: Day 6 Left | B13: =B12-C13 -> 1 | C13: =COUNTIF(E$17:E$995, "Completed Day 6") -> 0
A14: Day 7 Left | B14: =B13-C14 -> 1 | C14: =COUNTIF(E$17:E$995, "Completed Day 7") -> 0
A16: Task ID | B16: Feature ID | C16: Assigned To | D16: Description | E16: Status | F16: Notes
A17: 1 | D17: --> Add tasks to complete each feature for this sprint | F17: You are free to determine your own algorithm for mapping the (now) 21 days of this sprint to the 7 reporting days – e.g., 1/3 days, the first 7 days you actually do work, etc.
A18: 2
A19: 3
A20: 4
A21: 5
A22: 6
A23: 7
A24: 8
A25: 9
A26: 10
A27: 11
A28: 12
A29: 13
... A100: 84
